Running from arcus-1.ics.uci.edu
2019-05-13 07:42:03.056380: I tensorflow/core/common_runtime/gpu/gpu_device.cc:1405] Found device 0 with properties: 
name: GeForce GTX TITAN major: 3 minor: 5 memoryClockRate(GHz): 0.8755
pciBusID: 0000:03:00.0
totalMemory: 5.94GiB freeMemory: 5.87GiB
2019-05-13 07:42:03.056628: I tensorflow/core/common_runtime/gpu/gpu_device.cc:1484] Adding visible gpu devices: 0
2019-05-13 07:42:03.477772: I tensorflow/core/common_runtime/gpu/gpu_device.cc:965] Device interconnect StreamExecutor with strength 1 edge matrix:
2019-05-13 07:42:03.477837: I tensorflow/core/common_runtime/gpu/gpu_device.cc:971]      0 
2019-05-13 07:42:03.477852: I tensorflow/core/common_runtime/gpu/gpu_device.cc:984] 0:   N 
2019-05-13 07:42:03.478144: I tensorflow/core/common_runtime/gpu/gpu_device.cc:1097] Created TensorFlow device (/job:localhost/replica:0/task:0/device:GPU:0 with 5662 MB memory) -> physical GPU (device: 0, name: GeForce GTX TITAN, pci bus id: 0000:03:00.0, compute capability: 3.5)
/pkg/python/3.6.1-centos7/lib/python3.6/site-packages/h5py/__init__.py:34: FutureWarning: Conversion of the second argument of issubdtype from `float` to `np.floating` is deprecated. In future, it will be treated as `np.float64 == np.dtype(float).type`.
  from ._conv import register_converters as _register_converters
Using TensorFlow backend.
{'alpha': 0.7134294648716323, 'dropout': 0.32962542683487855, 'lr': 0.004047309454229736, 'leaky_relu': 0.23621254943637693, 'batch_norm': 1, 'loss_type': 'weak_loss', 'num_layers': 2, 'layer_0': 271, 'layer_1': 265, 'layer_2': 204, 'layer_3': 229, 'layer_4': 430, 'layer_5': 372, 'layer_6': 406, 'layer_7': 184, 'max_concurrent': 3, 'P': 'arcus_gpu.p', 'q': 'arcus.q', 'l': "hostname='(arcus-1|arcus-2|arcus-3|arcus-4|arcus-5|arcus-6|arcus-7|arcus-8|arcus-9|arcus-10)'", 'env': '/home/jott1/Projects/SHERPA_EX/.profile', 'data': 'fluxbypass_aqua', 'run_type': 'hyper_param_opt', 'batch_size': 2048, 'data_dir': '/baldig/chemistry/earth_system_science/', 'max_dense_layers': 8, 'epochs': 100, 'patience': 10, 'conservation': 0}
Epoch 1/100
Traceback (most recent call last):
  File "/home/jott1/.local/lib/python3.6/site-packages/pymongo/pool.py", line 973, in connect
    sock = _configured_socket(self.address, self.opts)
  File "/home/jott1/.local/lib/python3.6/site-packages/pymongo/pool.py", line 848, in _configured_socket
    sock = _create_connection(address, options)
  File "/home/jott1/.local/lib/python3.6/site-packages/pymongo/pool.py", line 829, in _create_connection
    raise err
  File "/home/jott1/.local/lib/python3.6/site-packages/pymongo/pool.py", line 822, in _create_connection
    sock.connect(sa)
ConnectionRefusedError: [Errno 111] Connection refused

During handling of the above exception, another exception occurred:

Traceback (most recent call last):
  File "main.py", line 72, in <module>
    # save lr model
  File "/home/jott1/Projects/CBRAIN-CAM/notebooks/tbeucler_devlog/hp_opt_conservation/model.py", line 135, in train
    callbacks=callbacks,
  File "/home/jott1/.local/lib/python3.6/site-packages/tensorflow/python/keras/engine/training.py", line 1779, in fit_generator
    initial_epoch=initial_epoch)
  File "/home/jott1/.local/lib/python3.6/site-packages/tensorflow/python/keras/engine/training_generator.py", line 244, in fit_generator
    callbacks.on_epoch_end(epoch, epoch_logs)
  File "/home/jott1/.local/lib/python3.6/site-packages/tensorflow/python/keras/callbacks.py", line 96, in on_epoch_end
    callback.on_epoch_end(epoch, logs)
  File "/home/jott1/.local/lib/python3.6/site-packages/sherpa/database.py", line 226, in <lambda>
    context={n: logs[n] for n in context_names})
  File "/home/jott1/.local/lib/python3.6/site-packages/sherpa/database.py", line 209, in send_metrics
    self.db.results.insert_one(result)
  File "/home/jott1/.local/lib/python3.6/site-packages/pymongo/collection.py", line 700, in insert_one
    session=session),
  File "/home/jott1/.local/lib/python3.6/site-packages/pymongo/collection.py", line 614, in _insert
    bypass_doc_val, session)
  File "/home/jott1/.local/lib/python3.6/site-packages/pymongo/collection.py", line 602, in _insert_one
    acknowledged, _insert_command, session)
  File "/home/jott1/.local/lib/python3.6/site-packages/pymongo/mongo_client.py", line 1280, in _retryable_write
    return self._retry_with_session(retryable, func, s, None)
  File "/home/jott1/.local/lib/python3.6/site-packages/pymongo/mongo_client.py", line 1226, in _retry_with_session
    with self._get_socket(server) as sock_info:
  File "/pkg/python/3.6.1-centos7/lib/python3.6/contextlib.py", line 82, in __enter__
    return next(self.gen)
  File "/home/jott1/.local/lib/python3.6/site-packages/pymongo/mongo_client.py", line 1094, in _get_socket
    with server.get_socket(self.__all_credentials) as sock_info:
  File "/pkg/python/3.6.1-centos7/lib/python3.6/contextlib.py", line 82, in __enter__
    return next(self.gen)
  File "/home/jott1/.local/lib/python3.6/site-packages/pymongo/pool.py", line 1009, in get_socket
    sock_info = self._get_socket_no_auth()
  File "/home/jott1/.local/lib/python3.6/site-packages/pymongo/pool.py", line 1049, in _get_socket_no_auth
    sock_info = self._check(sock_info)
  File "/home/jott1/.local/lib/python3.6/site-packages/pymongo/pool.py", line 1100, in _check
    return self.connect()
  File "/home/jott1/.local/lib/python3.6/site-packages/pymongo/pool.py", line 977, in connect
    _raise_connection_failure(self.address, error)
  File "/home/jott1/.local/lib/python3.6/site-packages/pymongo/pool.py", line 283, in _raise_connection_failure
    raise AutoReconnect(msg)
pymongo.errors.AutoReconnect: arcus-1.ics.uci.edu:27001: [Errno 111] Connection refused
