Running from arcus-6
2019-05-14 10:42:13.227584: I tensorflow/core/platform/cpu_feature_guard.cc:141] Your CPU supports instructions that this TensorFlow binary was not compiled to use: AVX2 FMA
2019-05-14 10:42:14.091929: I tensorflow/core/common_runtime/gpu/gpu_device.cc:1405] Found device 0 with properties: 
name: GeForce GTX TITAN X major: 5 minor: 2 memoryClockRate(GHz): 1.076
pciBusID: 0000:03:00.0
totalMemory: 11.93GiB freeMemory: 11.81GiB
2019-05-14 10:42:14.091992: I tensorflow/core/common_runtime/gpu/gpu_device.cc:1484] Adding visible gpu devices: 0
2019-05-14 10:42:23.348796: I tensorflow/core/common_runtime/gpu/gpu_device.cc:965] Device interconnect StreamExecutor with strength 1 edge matrix:
2019-05-14 10:42:23.349159: I tensorflow/core/common_runtime/gpu/gpu_device.cc:971]      0 
2019-05-14 10:42:23.349186: I tensorflow/core/common_runtime/gpu/gpu_device.cc:984] 0:   N 
2019-05-14 10:42:23.349831: I tensorflow/core/common_runtime/gpu/gpu_device.cc:1097] Created TensorFlow device (/job:localhost/replica:0/task:0/device:GPU:0 with 11428 MB memory) -> physical GPU (device: 0, name: GeForce GTX TITAN X, pci bus id: 0000:03:00.0, compute capability: 5.2)
{'alpha': 0.5917636902175802, 'dropout': 0.18785918730719758, 'lr': 0.007037183823240194, 'leaky_relu': 0.2753364079445441, 'batch_norm': 1, 'loss_type': 'weak_loss', 'num_layers': 6, 'layer_0': 458, 'layer_1': 277, 'layer_2': 387, 'layer_3': 371, 'layer_4': 238, 'layer_5': 121, 'layer_6': 429, 'layer_7': 103, 'max_concurrent': 4, 'P': 'arcus_gpu.p', 'q': 'arcus.q', 'l': "hostname='(arcus-1|arcus-2|arcus-3|arcus-4|arcus-5|arcus-6|arcus-7|arcus-8|arcus-9|arcus-10)'", 'env': '/home/jott1/Projects/SHERPA_EX/.profile', 'data': 'fluxbypass_aqua', 'run_type': 'hyper_param_opt_conservation', 'batch_size': 2048, 'data_dir': '/baldig/chemistry/earth_system_science/', 'max_dense_layers': 8, 'epochs': 25, 'patience': 10, 'conservation': 0}
Epoch 1/25
 - 5232s - loss: -1.9277e+12 - mean_squared_error: 1412602928556.3083 - val_loss: -7.9494e+12 - val_mean_squared_error: 5822952669090.5488
/pkg/python/3.6.1-centos7/lib/python3.6/site-packages/h5py/__init__.py:34: FutureWarning: Conversion of the second argument of issubdtype from `float` to `np.floating` is deprecated. In future, it will be treated as `np.float64 == np.dtype(float).type`.
  from ._conv import register_converters as _register_converters
Using TensorFlow backend.
Epoch 2/25
Traceback (most recent call last):
  File "main.py", line 76, in <module>
    net.train(train_gen, valid_gen, trial=trial, client=client)
  File "/home/jott1/Projects/CBRAIN-CAM/notebooks/tbeucler_devlog/hp_opt_conservation/model.py", line 135, in train
    # save to h5 file
  File "/home/jott1/.local/lib/python3.6/site-packages/tensorflow/python/keras/engine/training.py", line 1779, in fit_generator
    initial_epoch=initial_epoch)
  File "/home/jott1/.local/lib/python3.6/site-packages/tensorflow/python/keras/engine/training_generator.py", line 244, in fit_generator
    callbacks.on_epoch_end(epoch, epoch_logs)
  File "/home/jott1/.local/lib/python3.6/site-packages/tensorflow/python/keras/callbacks.py", line 96, in on_epoch_end
    callback.on_epoch_end(epoch, logs)
  File "/home/jott1/.local/lib/python3.6/site-packages/sherpa/database.py", line 226, in <lambda>
    context={n: logs[n] for n in context_names})
  File "/home/jott1/.local/lib/python3.6/site-packages/sherpa/database.py", line 209, in send_metrics
    self.db.results.insert_one(result)
  File "/home/jott1/.local/lib/python3.6/site-packages/pymongo/collection.py", line 700, in insert_one
    session=session),
  File "/home/jott1/.local/lib/python3.6/site-packages/pymongo/collection.py", line 614, in _insert
    bypass_doc_val, session)
  File "/home/jott1/.local/lib/python3.6/site-packages/pymongo/collection.py", line 602, in _insert_one
    acknowledged, _insert_command, session)
  File "/home/jott1/.local/lib/python3.6/site-packages/pymongo/mongo_client.py", line 1279, in _retryable_write
    with self._tmp_session(session) as s:
  File "/pkg/python/3.6.1-centos7/lib/python3.6/contextlib.py", line 82, in __enter__
    return next(self.gen)
  File "/home/jott1/.local/lib/python3.6/site-packages/pymongo/mongo_client.py", line 1611, in _tmp_session
    s = self._ensure_session(session)
  File "/home/jott1/.local/lib/python3.6/site-packages/pymongo/mongo_client.py", line 1598, in _ensure_session
    return self.__start_session(True, causal_consistency=False)
  File "/home/jott1/.local/lib/python3.6/site-packages/pymongo/mongo_client.py", line 1551, in __start_session
    server_session = self._get_server_session()
  File "/home/jott1/.local/lib/python3.6/site-packages/pymongo/mongo_client.py", line 1584, in _get_server_session
    return self._topology.get_server_session()
  File "/home/jott1/.local/lib/python3.6/site-packages/pymongo/topology.py", line 429, in get_server_session
    None)
  File "/home/jott1/.local/lib/python3.6/site-packages/pymongo/topology.py", line 200, in _select_servers_loop
    self._error_message(selector))
pymongo.errors.ServerSelectionTimeoutError: arcus-2.ics.uci.edu:27001: [Errno 111] Connection refused
