Running from arcus-1.ics.uci.edu
2019-05-19 07:04:11.067940: E tensorflow/stream_executor/cuda/cuda_driver.cc:397] failed call to cuInit: CUDA_ERROR_NO_DEVICE
2019-05-19 07:04:11.068332: I tensorflow/stream_executor/cuda/cuda_diagnostics.cc:163] retrieving CUDA diagnostic information for host: arcus-1.ics.uci.edu
2019-05-19 07:04:11.068361: I tensorflow/stream_executor/cuda/cuda_diagnostics.cc:170] hostname: arcus-1.ics.uci.edu
2019-05-19 07:04:11.068480: I tensorflow/stream_executor/cuda/cuda_diagnostics.cc:194] libcuda reported version is: 396.26.0
2019-05-19 07:04:11.068665: I tensorflow/stream_executor/cuda/cuda_diagnostics.cc:198] kernel reported version is: 396.26.0
2019-05-19 07:04:11.068691: I tensorflow/stream_executor/cuda/cuda_diagnostics.cc:305] kernel version seems to match DSO: 396.26.0
/pkg/python/3.6.1-centos7/lib/python3.6/site-packages/h5py/__init__.py:34: FutureWarning: Conversion of the second argument of issubdtype from `float` to `np.floating` is deprecated. In future, it will be treated as `np.float64 == np.dtype(float).type`.
  from ._conv import register_converters as _register_converters
Using TensorFlow backend.
Traceback (most recent call last):
  File "main.py", line 101, in <module>
    net.save()
  File "/home/jott1/Projects/CBRAIN-CAM/notebooks/tbeucler_devlog/hp_opt_conservation/model.py", line 151, in save
    self.model.save(file_name+'.h5')
  File "/home/jott1/.local/lib/python3.6/site-packages/tensorflow/python/keras/engine/network.py", line 1278, in save
    save_model(self, filepath, overwrite, include_optimizer)
  File "/home/jott1/.local/lib/python3.6/site-packages/tensorflow/python/keras/engine/saving.py", line 89, in save_model
    f = h5py.File(filepath, mode='w')
  File "/pkg/python/3.6.1-centos7/lib/python3.6/site-packages/h5py/_hl/files.py", line 271, in __init__
    fid = make_fid(name, mode, userblock_size, fapl, swmr=swmr)
  File "/pkg/python/3.6.1-centos7/lib/python3.6/site-packages/h5py/_hl/files.py", line 107, in make_fid
    fid = h5f.create(name, h5f.ACC_TRUNC, fapl=fapl, fcpl=fcpl)
  File "h5py/_objects.pyx", line 54, in h5py._objects.with_phil.wrapper (/tmp/pip-s_7obrrg-build/h5py/_objects.c:2840)
  File "h5py/_objects.pyx", line 55, in h5py._objects.with_phil.wrapper (/tmp/pip-s_7obrrg-build/h5py/_objects.c:2798)
  File "h5py/h5f.pyx", line 98, in h5py.h5f.create (/tmp/pip-s_7obrrg-build/h5py/h5f.c:2284)
OSError: Unable to create file (Unable to open file: name = 'sherparesults/fluxbypass_aqua_local/normal_mse/models/00009.h5', errno = 2, error message = 'no such file or directory', flags = 13, o_flags = 242)
