Running from arcus-4.ics.uci.edu
2019-05-17 02:33:57.838102: I tensorflow/core/common_runtime/gpu/gpu_device.cc:1405] Found device 0 with properties: 
name: GeForce GTX TITAN Black major: 3 minor: 5 memoryClockRate(GHz): 0.98
pciBusID: 0000:02:00.0
totalMemory: 5.94GiB freeMemory: 5.86GiB
2019-05-17 02:33:57.838549: I tensorflow/core/common_runtime/gpu/gpu_device.cc:1484] Adding visible gpu devices: 0
2019-05-17 02:34:07.999203: I tensorflow/core/common_runtime/gpu/gpu_device.cc:965] Device interconnect StreamExecutor with strength 1 edge matrix:
2019-05-17 02:34:07.999299: I tensorflow/core/common_runtime/gpu/gpu_device.cc:971]      0 
2019-05-17 02:34:07.999328: I tensorflow/core/common_runtime/gpu/gpu_device.cc:984] 0:   N 
2019-05-17 02:34:07.999819: I tensorflow/core/common_runtime/gpu/gpu_device.cc:1097] Created TensorFlow device (/job:localhost/replica:0/task:0/device:GPU:0 with 5658 MB memory) -> physical GPU (device: 0, name: GeForce GTX TITAN Black, pci bus id: 0000:02:00.0, compute capability: 3.5)
Epoch 1/25
 - 4745s - loss: -3.2604e+08 - mean_squared_error: 456770172.6362 - val_loss: -8.3257e+09 - val_mean_squared_error: 11672779560.8592
Epoch 2/25
 - 4728s - loss: -7.2448e+10 - mean_squared_error: 101450731800.7981 - val_loss: -4.0450e+11 - val_mean_squared_error: 566275916235.6689
Epoch 3/25
 - 5196s - loss: -8.8794e+11 - mean_squared_error: 1243496379090.2646 - val_loss: -2.2208e+12 - val_mean_squared_error: 3108552936331.9785
Epoch 4/25
 - 4880s - loss: -4.2878e+12 - mean_squared_error: 6005108112254.9111 - val_loss: -1.5895e+13 - val_mean_squared_error: 22250939075991.8594
/pkg/python/3.6.1-centos7/lib/python3.6/site-packages/h5py/__init__.py:34: FutureWarning: Conversion of the second argument of issubdtype from `float` to `np.floating` is deprecated. In future, it will be treated as `np.float64 == np.dtype(float).type`.
  from ._conv import register_converters as _register_converters
Using TensorFlow backend.
Epoch 5/25
Traceback (most recent call last):
  File "main.py", line 98, in <module>
    
  File "/home/jott1/Projects/CBRAIN-CAM/notebooks/tbeucler_devlog/hp_opt_conservation/model.py", line 130, in train
    callbacks=callbacks,
  File "/home/jott1/.local/lib/python3.6/site-packages/tensorflow/python/keras/engine/training.py", line 1779, in fit_generator
    initial_epoch=initial_epoch)
  File "/home/jott1/.local/lib/python3.6/site-packages/tensorflow/python/keras/engine/training_generator.py", line 244, in fit_generator
    callbacks.on_epoch_end(epoch, epoch_logs)
  File "/home/jott1/.local/lib/python3.6/site-packages/tensorflow/python/keras/callbacks.py", line 96, in on_epoch_end
    callback.on_epoch_end(epoch, logs)
  File "/home/jott1/.local/lib/python3.6/site-packages/sherpa/database.py", line 226, in <lambda>
    context={n: logs[n] for n in context_names})
  File "/home/jott1/.local/lib/python3.6/site-packages/sherpa/database.py", line 209, in send_metrics
    self.db.results.insert_one(result)
  File "/home/jott1/.local/lib/python3.6/site-packages/pymongo/collection.py", line 700, in insert_one
    session=session),
  File "/home/jott1/.local/lib/python3.6/site-packages/pymongo/collection.py", line 614, in _insert
    bypass_doc_val, session)
  File "/home/jott1/.local/lib/python3.6/site-packages/pymongo/collection.py", line 602, in _insert_one
    acknowledged, _insert_command, session)
  File "/home/jott1/.local/lib/python3.6/site-packages/pymongo/mongo_client.py", line 1279, in _retryable_write
    with self._tmp_session(session) as s:
  File "/pkg/python/3.6.1-centos7/lib/python3.6/contextlib.py", line 82, in __enter__
    return next(self.gen)
  File "/home/jott1/.local/lib/python3.6/site-packages/pymongo/mongo_client.py", line 1611, in _tmp_session
    s = self._ensure_session(session)
  File "/home/jott1/.local/lib/python3.6/site-packages/pymongo/mongo_client.py", line 1598, in _ensure_session
    return self.__start_session(True, causal_consistency=False)
  File "/home/jott1/.local/lib/python3.6/site-packages/pymongo/mongo_client.py", line 1551, in __start_session
    server_session = self._get_server_session()
  File "/home/jott1/.local/lib/python3.6/site-packages/pymongo/mongo_client.py", line 1584, in _get_server_session
    return self._topology.get_server_session()
  File "/home/jott1/.local/lib/python3.6/site-packages/pymongo/topology.py", line 429, in get_server_session
    None)
  File "/home/jott1/.local/lib/python3.6/site-packages/pymongo/topology.py", line 200, in _select_servers_loop
    self._error_message(selector))
pymongo.errors.ServerSelectionTimeoutError: arcus-2.ics.uci.edu:27003: [Errno 111] Connection refused
