Running from arcus-1.ics.uci.edu
2019-05-16 10:26:56.848648: I tensorflow/core/common_runtime/gpu/gpu_device.cc:1405] Found device 0 with properties: 
name: GeForce GTX TITAN major: 3 minor: 5 memoryClockRate(GHz): 0.8755
pciBusID: 0000:84:00.0
totalMemory: 5.94GiB freeMemory: 5.87GiB
2019-05-16 10:26:56.848946: I tensorflow/core/common_runtime/gpu/gpu_device.cc:1484] Adding visible gpu devices: 0
2019-05-16 10:27:00.067405: I tensorflow/core/common_runtime/gpu/gpu_device.cc:965] Device interconnect StreamExecutor with strength 1 edge matrix:
2019-05-16 10:27:00.067467: I tensorflow/core/common_runtime/gpu/gpu_device.cc:971]      0 
2019-05-16 10:27:00.067482: I tensorflow/core/common_runtime/gpu/gpu_device.cc:984] 0:   N 
2019-05-16 10:27:00.067761: I tensorflow/core/common_runtime/gpu/gpu_device.cc:1097] Created TensorFlow device (/job:localhost/replica:0/task:0/device:GPU:0 with 5662 MB memory) -> physical GPU (device: 0, name: GeForce GTX TITAN, pci bus id: 0000:84:00.0, compute capability: 3.5)
{'alpha': 0.2028489542952553, 'dropout': 0.2607992746676282, 'lr': 0.005295830281319637, 'leaky_relu': 0.19556592335816647, 'batch_norm': 1, 'num_layers': 2, 'layer_0': 409, 'layer_1': 465, 'layer_2': 511, 'layer_3': 288, 'layer_4': 77, 'layer_5': 184, 'layer_6': 72, 'layer_7': 108, 'max_concurrent': 3, 'P': 'arcus_gpu.p', 'q': 'arcus.q', 'l': "hostname='(arcus-1|arcus-2|arcus-3|arcus-4|arcus-5|arcus-6|arcus-7|arcus-8|arcus-9|arcus-10)'", 'env': '/home/jott1/Projects/SHERPA_EX/.profile', 'data': 'fluxbypass_aqua', 'net_type': 'normal', 'loss_type': 'mse', 'batch_size': 2048, 'data_dir': '/baldig/chemistry/earth_system_science/', 'max_dense_layers': 8, 'epochs': 25, 'patience': 10}
Epoch 1/25
 - 3710s - loss: 406.5186 - mean_squared_error: 406.5186 - val_loss: 290.4927 - val_mean_squared_error: 290.4927
Epoch 2/25
 - 4772s - loss: 384.8858 - mean_squared_error: 384.8858 - val_loss: 319.8341 - val_mean_squared_error: 319.8341
Epoch 3/25
 - 5040s - loss: 382.0385 - mean_squared_error: 382.0385 - val_loss: 296.7289 - val_mean_squared_error: 296.7289
Epoch 4/25
 - 4878s - loss: 381.0700 - mean_squared_error: 381.0700 - val_loss: 290.4603 - val_mean_squared_error: 290.4603
Epoch 5/25
 - 4221s - loss: 379.9260 - mean_squared_error: 379.9260 - val_loss: 283.7950 - val_mean_squared_error: 283.7950
Epoch 6/25
 - 4591s - loss: 379.3881 - mean_squared_error: 379.3881 - val_loss: 295.7688 - val_mean_squared_error: 295.7688
Epoch 7/25
 - 4523s - loss: 379.1008 - mean_squared_error: 379.1008 - val_loss: 306.0443 - val_mean_squared_error: 306.0443
Epoch 8/25
 - 4637s - loss: 378.3957 - mean_squared_error: 378.3957 - val_loss: 305.4143 - val_mean_squared_error: 305.4143
Epoch 9/25
 - 4592s - loss: 378.1418 - mean_squared_error: 378.1418 - val_loss: 318.6166 - val_mean_squared_error: 318.6166
Epoch 10/25
 - 4618s - loss: 378.1751 - mean_squared_error: 378.1751 - val_loss: 330.6962 - val_mean_squared_error: 330.6962
Epoch 11/25
 - 5183s - loss: 377.8258 - mean_squared_error: 377.8258 - val_loss: 319.3215 - val_mean_squared_error: 319.3215
Epoch 12/25
 - 5274s - loss: 377.5252 - mean_squared_error: 377.5252 - val_loss: 282.3991 - val_mean_squared_error: 282.3991
Epoch 13/25
 - 4594s - loss: 377.5970 - mean_squared_error: 377.5970 - val_loss: 299.3601 - val_mean_squared_error: 299.3601
Epoch 14/25
 - 5061s - loss: 377.5180 - mean_squared_error: 377.5180 - val_loss: 316.2326 - val_mean_squared_error: 316.2326
Epoch 15/25
 - 5340s - loss: 377.4481 - mean_squared_error: 377.4481 - val_loss: 311.2077 - val_mean_squared_error: 311.2077
Epoch 16/25
 - 5168s - loss: 377.5250 - mean_squared_error: 377.5250 - val_loss: 315.5520 - val_mean_squared_error: 315.5520
/pkg/python/3.6.1-centos7/lib/python3.6/site-packages/h5py/__init__.py:34: FutureWarning: Conversion of the second argument of issubdtype from `float` to `np.floating` is deprecated. In future, it will be treated as `np.float64 == np.dtype(float).type`.
  from ._conv import register_converters as _register_converters
Using TensorFlow backend.
Epoch 17/25
Traceback (most recent call last):
  File "main.py", line 76, in <module>
    batch_size=trial.parameters['batch_size'],
  File "/home/jott1/Projects/CBRAIN-CAM/notebooks/tbeucler_devlog/hp_opt_conservation/model.py", line 121, in train
    if trial is not None: callbacks.append(client.keras_send_metrics(trial, objective_name='val_loss', context_names=['loss', 'val_loss']))
  File "/home/jott1/.local/lib/python3.6/site-packages/tensorflow/python/keras/engine/training.py", line 1779, in fit_generator
    initial_epoch=initial_epoch)
  File "/home/jott1/.local/lib/python3.6/site-packages/tensorflow/python/keras/engine/training_generator.py", line 244, in fit_generator
    callbacks.on_epoch_end(epoch, epoch_logs)
  File "/home/jott1/.local/lib/python3.6/site-packages/tensorflow/python/keras/callbacks.py", line 96, in on_epoch_end
    callback.on_epoch_end(epoch, logs)
  File "/home/jott1/.local/lib/python3.6/site-packages/sherpa/database.py", line 226, in <lambda>
    context={n: logs[n] for n in context_names})
  File "/home/jott1/.local/lib/python3.6/site-packages/sherpa/database.py", line 209, in send_metrics
    self.db.results.insert_one(result)
  File "/home/jott1/.local/lib/python3.6/site-packages/pymongo/collection.py", line 700, in insert_one
    session=session),
  File "/home/jott1/.local/lib/python3.6/site-packages/pymongo/collection.py", line 614, in _insert
    bypass_doc_val, session)
  File "/home/jott1/.local/lib/python3.6/site-packages/pymongo/collection.py", line 602, in _insert_one
    acknowledged, _insert_command, session)
  File "/home/jott1/.local/lib/python3.6/site-packages/pymongo/mongo_client.py", line 1279, in _retryable_write
    with self._tmp_session(session) as s:
  File "/pkg/python/3.6.1-centos7/lib/python3.6/contextlib.py", line 82, in __enter__
    return next(self.gen)
  File "/home/jott1/.local/lib/python3.6/site-packages/pymongo/mongo_client.py", line 1611, in _tmp_session
    s = self._ensure_session(session)
  File "/home/jott1/.local/lib/python3.6/site-packages/pymongo/mongo_client.py", line 1598, in _ensure_session
    return self.__start_session(True, causal_consistency=False)
  File "/home/jott1/.local/lib/python3.6/site-packages/pymongo/mongo_client.py", line 1551, in __start_session
    server_session = self._get_server_session()
  File "/home/jott1/.local/lib/python3.6/site-packages/pymongo/mongo_client.py", line 1584, in _get_server_session
    return self._topology.get_server_session()
  File "/home/jott1/.local/lib/python3.6/site-packages/pymongo/topology.py", line 429, in get_server_session
    None)
  File "/home/jott1/.local/lib/python3.6/site-packages/pymongo/topology.py", line 200, in _select_servers_loop
    self._error_message(selector))
pymongo.errors.ServerSelectionTimeoutError: arcus-2.ics.uci.edu:27004: [Errno 111] Connection refused
